<!DOCTYPE HTML PUBLIC "-//W3C//DTD HTML 3.2//EN">
<HTML>
 <HEAD>
   <TITLE> [JDEV] Viewing CVS on jabberstudio.org
   </TITLE>
   <LINK REL="Index" HREF="index.html" >
   <LINK REL="made" HREF="mailto:jdev%40jabber.org?Subject=%5BJDEV%5D%20Viewing%20CVS%20on%20jabberstudio.org&In-Reply-To=">
   <META NAME="robots" CONTENT="index,nofollow">
   <META http-equiv="Content-Type" content="text/html; charset=us-ascii">
   <LINK REL="Previous"  HREF="018094.html">
   <LINK REL="Next"  HREF="018100.html">
 </HEAD>
 <BODY BGCOLOR="#ffffff">
   <H1>[JDEV] Viewing CVS on jabberstudio.org</H1>
    <B>Menzi, Hans</B> 
    <A HREF="mailto:jdev%40jabber.org?Subject=%5BJDEV%5D%20Viewing%20CVS%20on%20jabberstudio.org&In-Reply-To="
       TITLE="[JDEV] Viewing CVS on jabberstudio.org">HMenzi at eci.com
       </A><BR>
    <I>Wed Nov 12 08:19:04 CST 2003</I>
    <P><UL>
        <LI>Previous message: <A HREF="018094.html">[JDEV] jabberd2 on Panther - Where's MySQL?
</A></li>
        <LI>Next message: <A HREF="018100.html">[JDEV] test
</A></li>
         <LI> <B>Messages sorted by:</B> 
              <a href="date.html#18097">[ date ]</a>
              <a href="thread.html#18097">[ thread ]</a>
              <a href="subject.html#18097">[ subject ]</a>
              <a href="author.html#18097">[ author ]</a>
         </LI>
       </UL>
    <HR>  
<!--beginarticle-->
<PRE>I get the following Exception message:

An Exception Has Occurred
Python Traceback
Traceback (most recent call last):
  File &quot;/usr/lib/python2.3/viewcvs/viewcvs.py&quot;, line 3088, in main
    request.run_viewcvs()
  File &quot;/usr/lib/python2.3/viewcvs/viewcvs.py&quot;, line 325, in run_viewcvs
    self.view_func(self)
  File &quot;/usr/lib/python2.3/viewcvs/viewcvs.py&quot;, line 1322, in
view_directory
    view_directory_cvs(request, data, sortby, sortdir)
  File &quot;/usr/lib/python2.3/viewcvs/viewcvs.py&quot;, line 1582, in
view_directory_cvs
    generate_page(request, cfg.templates.directory, data)
  File &quot;/usr/lib/python2.3/viewcvs/viewcvs.py&quot;, line 564, in
generate_page
    template.generate(sys.stdout, data)
  File &quot;/usr/lib/python2.3/viewcvs/ezt.py&quot;, line 233, in generate
    self._execute(self.program, fp, ctx)
  File &quot;/usr/lib/python2.3/viewcvs/ezt.py&quot;, line 348, in _execute
    step[0](step[1], fp, ctx)
  File &quot;/usr/lib/python2.3/viewcvs/ezt.py&quot;, line 388, in _cmd_if_any
    self._do_if(value, t_section, f_section, fp, ctx)
  File &quot;/usr/lib/python2.3/viewcvs/ezt.py&quot;, line 420, in _do_if
    self._execute(section, fp, ctx)
  File &quot;/usr/lib/python2.3/viewcvs/ezt.py&quot;, line 348, in _execute
    step[0](step[1], fp, ctx)
  File &quot;/usr/lib/python2.3/viewcvs/ezt.py&quot;, line 424, in _cmd_for
    list = _get_value(valref, ctx)
  File &quot;/usr/lib/python2.3/viewcvs/ezt.py&quot;, line 492, in _get_value
    raise UnknownReference(refname)
UnknownReference: params

-------------- next part --------------
An HTML attachment was scrubbed...
URL: <A HREF="https://www.jabber.org/jdev/attachments/20031112/184fc0bd/attachment.htm">https://www.jabber.org/jdev/attachments/20031112/184fc0bd/attachment.htm</A> 
</PRE>

<!--endarticle-->
    <HR>
    <P><UL>
        <!--threads-->
	<LI>Previous message: <A HREF="018094.html">[JDEV] jabberd2 on Panther - Where's MySQL?
</A></li>
	<LI>Next message: <A HREF="018100.html">[JDEV] test
</A></li>
         <LI> <B>Messages sorted by:</B> 
              <a href="date.html#18097">[ date ]</a>
              <a href="thread.html#18097">[ thread ]</a>
              <a href="subject.html#18097">[ subject ]</a>
              <a href="author.html#18097">[ author ]</a>
         </LI>
       </UL>

<hr>
<a href="http://mail.jabber.org/mailman/listinfo/jdev">More information about the JDev
mailing list</a><br>
</body></html>
